<?xml version="1.0"?>
<robot xmlns:xacro="http://www.ros.org/wiki/xacro">
    <xacro:include filename="inertial_macros.xacro" />

    <material name="white">
        <color rgba="1 1 1 1" />
    </material>

    <material name="orange">
        <color rgba="1 0.3 0.1 1" />
    </material>

    <material name="blue">
        <color rgba="0.2 0.2 1 1" />
    </material>

    <material name="black">
        <color rgba="0 0 0 1" />
    </material>

    <material name="red">
        <color rgba="1 0 0 1" />
    </material>

    <!-- BASE LINK -->
    <link name="base_link">
    </link>

    <!-- for SLAM -->
    <joint name="base_footprint_joint" type="fixed">
        <parent link="base_link" />
        <child link="base_footprint" />
        <origin xyz="0 0 0" rpy="0 0 0" />
    </joint>

    <!-- for SLAM -->
    <link name="base_footprint">
    </link>

    <!-- CHASSIS LINK -->
    <joint name="chassis_joint" type="fixed">
        <parent link="base_link" />
        <child link="chassis" />
        <!-- <origin xyz="-0.1 0 0" /> -->
        <origin xyz="0 0 0" rpy="0 0 0" />
        <!-- <axis xyz="0 1 0" /> -->
    </joint>

    <link name="chassis">
        <visual>
            <!-- <origin xyz="0.15 0 0.075" /> -->
            <!-- <origin xyz="0 0 0.11" /> -->
            <origin xyz="0 0 0.09" />
            <geometry>
                <!-- <box size="0.3 0.3 0.15" /> -->
                <cylinder radius="0.1" length="0.18" />
            </geometry>
            <material name="white" />
        </visual>

        <collision>
            <!-- <origin xyz="0.15 0 0.075" /> -->
            <origin xyz="0 0 0.11" />
            <geometry>
                <!-- <box size="0.3 0.3 0.15" /> -->
                <cylinder radius="0.1" length="0.18" />
            </geometry>
        </collision>

        <!-- <xacro:inertial_box mass="0.5" x="0.3" y="0.3" z="0.15">
         <origin xyz="0.15 0 0.075" rpy="0 0 0" />
          </xacro:inertial_box> -->
        <xacro:inertial_cylinder mass="0.5" radius="0.1" length="0.18">
            <origin xyz="0 0 0.11" rpy="0 0 0" />
        </xacro:inertial_cylinder>
    </link>

    <gazebo reference="chassis">
        <material>Gazebo/White</material>
    </gazebo>

    <!-- LEFT WHEEL LINK -->

    <joint name="left_wheel_joint" type="continuous">
        <parent link="base_link" />
        <child link="left_wheel" />
        <!-- <origin xyz="0 0.175 0" rpy="-${pi/2} 0 0" /> -->
        <origin xyz="0 0.12 0" rpy="-${pi/2} 0 0" />
        <axis xyz="0 0 1" />
    </joint>

    <link name="left_wheel">
        <visual>
            <geometry>
                <!-- <cylinder radius="0.04" length="0.04" /> -->
                <cylinder radius="0.04" length="0.036" />
            </geometry>
            <material name="blue" />
        </visual>

        <collision>
            <geometry>
                <!-- <cylinder radius="0.05" length="0.04" /> -->
                <!-- <sphere radius="0.05" /> -->
                <sphere radius="0.04" />
            </geometry>
        </collision>

        <!-- <xacro:inertial_cylinder mass="0.1" radius="0.05" length="0.04"> -->
        <xacro:inertial_cylinder mass="0.1" radius="0.04" length="0.036">
            <origin xyz="0 0 0" rpy="0 0 0" />
        </xacro:inertial_cylinder>
    </link>

    <gazebo reference="left_wheel">
        <material>Gazebo/Blue</material>
    </gazebo>

    <!-- RIGHT WHEEL LINK -->

    <joint name="right_wheel_joint" type="continuous">
        <parent link="base_link" />
        <child link="right_wheel" />
        <!-- <origin xyz="0 -0.175 0" rpy="${pi/2} 0 0" /> -->
        <origin xyz="0 -0.12 0" rpy="${pi/2} 0 0" />
        <axis xyz="0 0 -1" />
    </joint>

    <link name="right_wheel">
        <visual>
            <geometry>
                <!-- <cylinder radius="0.04" length="0.04" /> -->
                <cylinder radius="0.04" length="0.036" />
            </geometry>
            <material name="blue" />
        </visual>

        <collision>
            <geometry>
                <!-- <cylinder radius="0.05" length="0.04" /> -->
                <!-- <sphere radius="0.05" /> -->
                <sphere radius="0.04" />
            </geometry>
        </collision>

        <!-- <xacro:inertial_cylinder mass="0.1" radius="0.05" length="0.04"> -->
        <xacro:inertial_cylinder mass="0.1" radius="0.04" length="0.036">
            <origin xyz="0 0 0" rpy="0 0 0" />
        </xacro:inertial_cylinder>
    </link>

    <gazebo reference="right_wheel">
        <material>Gazebo/Blue</material>
    </gazebo>


    <!-- FRONT CASTER WHEEL LINK -->

    <joint name="front_caster_wheel_joint" type="fixed">
        <parent link="chassis" />
        <child link="front_caster_wheel" />
        <!-- <origin xyz="0.24 0 0" /> -->
        <origin xyz="0.075 0 -0.02" />
    </joint>

    <link name="front_caster_wheel">
        <visual>
            <origin xyz="0 0 0" />
            <geometry>
                <!-- <sphere radius="0.05" /> -->
                <sphere radius="0.02" />
            </geometry>
            <material name="black" />
        </visual>

        <collision>
            <origin xyz="0 0 0" />
            <geometry>
                <!-- <sphere radius="0.05" /> -->
                <sphere radius="0.02" />
            </geometry>
        </collision>

        <!-- <xacro:inertial_sphere mass="0.1" radius="0.05"> -->
        <xacro:inertial_sphere mass="0.1" radius="0.02">
            <origin xyz="0 0 0" rpy="0 0 0" />
        </xacro:inertial_sphere>
    </link>

    <gazebo reference="front_caster_wheel">
        <material>Gazebo/Black</material>
        <mu1 value="0.0001" />
        <mu2 value="0.0001" />
    </gazebo>

    <joint name="back_caster_wheel_joint" type="fixed">
        <parent link="chassis" />
        <child link="back_caster_wheel" />
        <!-- <origin xyz="0.24 0 0" /> -->
        <origin xyz="-0.075 0 -0.02" />
    </joint>

    <!-- BACK CASTER WHEEL -->

    <link name="back_caster_wheel">
        <visual>
            <origin xyz="0 0 0" />
            <geometry>
                <!-- <sphere radius="0.05" /> -->
                <sphere radius="0.02" />
            </geometry>
            <material name="black" />
        </visual>

        <collision>
            <origin xyz="0 0 0" />
            <geometry>
                <!-- <sphere radius="0.05" /> -->
                <sphere radius="0.02" />
            </geometry>
        </collision>

        <!-- <xacro:inertial_sphere mass="0.1" radius="0.05"> -->
        <xacro:inertial_sphere mass="0.1" radius="0.02">
            <origin xyz="0 0 0" rpy="0 0 0" />
        </xacro:inertial_sphere>
    </link>

    <gazebo reference="back_caster_wheel">
        <material>Gazebo/Black</material>
        <mu1 value="0.0001" />
        <mu2 value="0.0001" />
    </gazebo>


</robot>